Workbook
Name MAT_TYPE: [1]DATA_CUSA!$C$3:$C$9
Name PAIS_IP: '[2]Plantilla IP'!#REF!
Name RAMO: [1]DATA_CUSA!$A$3
Name SOC_406: [1]CAMPOS406!$C$7:$C$11
Name UMB: [1]DATA_CUSA!$E$3:$E$547

Sheet Plantilla
A1: Vista_Datos 1 | B1: Vista_Datos 1 | C1: Vista_Datos 1 | D1: Vista_Datos 1 | E1: Vista_Datos 1 | F1: Vista_Datos 1 | G1: Vista_Datos 1 | H1: Vista_Datos 2 | I1: Vista_Datos 2 | J1: Vista_Datos 2 | L1: Vista_Compras | M1: Vista_Compras | N1: Vista_Compras | O1: Vista_Compras | P1: Vista_Dat.ce/Almacenam.1 | R1: Vista_planificación | S1: Vista_planificación | T1: Vista_planificación | U1: Vista_planificación | V1: Vista_planificación | W1: Vista_planificación | X1: Vista_planificación | Y1: Vista_planificación | Z1: Vista_Dat.ce/Almacenam.2 | AA1: Vista_Dat.ce/Almacenam.2 | AE1: Vista_Contabilidad 1 | AF1: Vista_Contabilidad 1 | AH1: Vista_Contabilidad 1 | AI1: Vista_Datos 1 | AJ1: Vista_Contabilidad 1
A2: Ramo | B2: Tipo de material | C2: Texto breve de material (máximo 40 caracteres) | D2: Unidad de medida base | E2: Grupo de artículos COMPLETA DATOS MAESTROS | F2: Número de material antiguo MARA-BISMT | G2: Sector COMPLETA DATOS MAESTROS | H2: Información de fabricación/inspección COMPLETA DATOS MAESTROS | I2: Denominación de estándar COMPLETA DATOS MAESTROS | J2: Materia COMPLETA DATOS MAESTROS | K2: Centro | L2: Grupo de compras COMPLETA DATOS MAESTROS | M2: ID de impuestos material | N2: Ind. Ped.autom. COMPLETA DATOS MAESTROS | O2: Tmpo. Tratamiento EM COMPLETA DATOS MAESTROS | P2: Almacén | Q2: Característica de planificación de necesidades MARC-DISMM | R2: Punto de pedido MARC-MINBE | S2: Planificador de necesidades MARC-DISPO | T2: Tamaño de lote de planificación de necesidades MARC-DISLS | U2: Tamaño de lote mínimo MARC-BSTMI | V2: Tamaño de lote máximo MARC-BSTMA | W2: Stock máximo MARC-MABST | X2: Plazo de entrega previsto en días MARC-PLIFZ | Y2: Grupo de verificación p.verificación de disponibilidad MARC-MTVFP | Z2: Ubicación | AA2: Centro de beneficio COMPLETA DATOS MAESTROS | AB2: Numero Almacen | AC2: Tipo de Almacen | AD2: Ubicación | AE2: Tipo de valoración COMPLETA DATOS MAESTROS | AF2: Categoría de valoración COMPLETA DATOS MAESTROS | AG2: Precio variable | AH2: Indicador de control de precios COMPLETA DATOS MAESTROS | AI2: Texto largo de material | AJ2: Clase de valoración COMPLETA DATOS MAESTROS | AK2: Observaciones
A3: =+_xlfn.XLOOKUP(I3,Clases!A:A,Clases!O:O,0,0,1) -> E | B3: =+_xlfn.XLOOKUP(I3,Clases!A:A,Clases!Q:Q,0,0,1) -> ZSUM | C3: PAÑO:LIMPIA;PANTALLA;MICROFIBRA;XL | D3: UN | E3: =+_xlfn.XLOOKUP(I3,Clases!A:A,Clases!N:N,0,0,1) -> SUM231200 | G3: =+_xlfn.XLOOKUP(I3,Clases!A:A,Clases!P:P,0,0,1) -> 50 | H3: =+_xlfn.XLOOKUP(I3,Clases!A:A,Clases!R:R,0,0,1) -> 47131800 | I3: 038710 | J3: =+_xlfn.XLOOKUP(I3,Clases!A:A,Clases!M:M,0,0,1) -> CMI02130200 | K3: 6000 | L3: X20 | M3: 1 | N3: X | O3: 7 | P3: 1000 | Q3: ND | Y3: Y2 | AA3: =+_xlfn.CONCAT(K3,"01") -> 600001 | AB3: 601 | AC3: T01 | AE3: =+IF(B3="ZHER","M",IF(B3="ZRPI","C","")) | AF3: 3022 | AG3: 1 | AH3: V | AI3: PAÑO DE MICROFIBRA TAMAÑO XL PARA LIMPIEZA DE PANTALLAS; MARCA WHOOSH; PRESENTACIÓN EN PAQUETE | AJ3: =+IF(B3="ZHER","NUEVAHER",IF(B3="ZRPI","NUEVOREP",""))
A4: =+_xlfn.XLOOKUP(I4,Clases!A:A,Clases!O:O,0,0,1) -> E | B4: =+_xlfn.XLOOKUP(I4,Clases!A:A,Clases!Q:Q,0,0,1) -> ZSEG | C4: CAMISA:ALGODON;SOLDADOR;TALLA;M | D4: UN | E4: =+_xlfn.XLOOKUP(I4,Clases!A:A,Clases!N:N,0,0,1) -> SEG221100 | G4: =+_xlfn.XLOOKUP(I4,Clases!A:A,Clases!P:P,0,0,1) -> 50 | H4: =+_xlfn.XLOOKUP(I4,Clases!A:A,Clases!R:R,0,0,1) -> 53101602 | I4: 047577 | J4: =+_xlfn.XLOOKUP(I4,Clases!A:A,Clases!M:M,0,0,1) -> CMI02170400 | K4: 6E91 | L4: X19 | M4: 1 | N4: X | O4: 7 | P4: 1000 | Q4: ND | Y4: Y2 | AA4: =+_xlfn.CONCAT(K4,"01") -> 6E9101 | AB4: 6ET | AC4: T01 | AE4: =+IF(B4="ZHER","M",IF(B4="ZRPI","C","")) | AF4: 3141 | AG4: 1 | AH4: V | AI4: CAMISA DE SEGURIDAD PARA SOLDADOR; MARCA STANCO; MATERIAL 100% ALGODON; TALLA M | AJ4: =+IF(B4="ZHER","NUEVAHER",IF(B4="ZRPI","NUEVOREP",""))
A5: =+_xlfn.XLOOKUP(I5,Clases!A:A,Clases!O:O,0,0,1) -> E | B5: =+_xlfn.XLOOKUP(I5,Clases!A:A,Clases!Q:Q,0,0,1) -> ZSEG | C5: CAMISA:ALGODON;SOLDADOR;TALLA;L | D5: UN | E5: =+_xlfn.XLOOKUP(I5,Clases!A:A,Clases!N:N,0,0,1) -> SEG221100 | G5: =+_xlfn.XLOOKUP(I5,Clases!A:A,Clases!P:P,0,0,1) -> 50 | H5: =+_xlfn.XLOOKUP(I5,Clases!A:A,Clases!R:R,0,0,1) -> 53101602 | I5: 047577 | J5: =+_xlfn.XLOOKUP(I5,Clases!A:A,Clases!M:M,0,0,1) -> CMI02170400 | K5: 6E91 | L5: X19 | M5: 1 | N5: X | O5: 7 | P5: 1000 | Q5: ND | Y5: Y2 | AA5: =+_xlfn.CONCAT(K5,"01") -> 6E9101 | AB5: 6ET | AC5: T01 | AE5: =+IF(B5="ZHER","M",IF(B5="ZRPI","C","")) | AF5: 3141 | AG5: 1 | AH5: V | AI5: CAMISA DE SEGURIDAD PARA SOLDADOR; MARCA STANCO; MATERIAL 100% ALGODON; TALLA L | AJ5: =+IF(B5="ZHER","NUEVAHER",IF(B5="ZRPI","NUEVOREP",""))
A6: =+_xlfn.XLOOKUP(I6,Clases!A:A,Clases!O:O,0,0,1) -> E | B6: =+_xlfn.XLOOKUP(I6,Clases!A:A,Clases!Q:Q,0,0,1) -> ZSEG | C6: CAMISA:ALGODON;SOLDADOR;TALLA;XL | D6: UN | E6: =+_xlfn.XLOOKUP(I6,Clases!A:A,Clases!N:N,0,0,1) -> SEG221100 | G6: =+_xlfn.XLOOKUP(I6,Clases!A:A,Clases!P:P,0,0,1) -> 50 | H6: =+_xlfn.XLOOKUP(I6,Clases!A:A,Clases!R:R,0,0,1) -> 53101602 | I6: 047577 | J6: =+_xlfn.XLOOKUP(I6,Clases!A:A,Clases!M:M,0,0,1) -> CMI02170400 | K6: 6E91 | L6: X19 | M6: 1 | N6: X | O6: 7 | P6: 1000 | Q6: ND | Y6: Y2 | AA6: =+_xlfn.CONCAT(K6,"01") -> 6E9101 | AB6: 6ET | AC6: T01 | AE6: =+IF(B6="ZHER","M",IF(B6="ZRPI","C","")) | AF6: 3141 | AG6: 1 | AH6: V | AI6: CAMISA DE SEGURIDAD PARA SOLDADOR; MARCA STANCO; MATERIAL 100% ALGODON; TALLA XL | AJ6: =+IF(B6="ZHER","NUEVAHER",IF(B6="ZRPI","NUEVOREP",""))

Sheet Clases
A1: Código | B1: Denominación | C1: Código Completo | D1: Categoría CMI | E1: Clave de Valores de Compras | F1: Unidad de Negocio | G1: Grupo de Artículos | H1: Ramo | I1: Sector | J1: Tipo de Material | K1: UNSPSC | L1: ID | M1: Categoría CMI | N1: Grupo de Artículos | O1: Ramo | P1: Sector | Q1: Tipo de Material | R1: UNSPSC
A2: 053111 | B2: PINTURAS:DECORATIVAS | D2: CMI01030400 - Otro-Mobiliario | F2: DEN | G2: ART371000 - Obras de arte | H2: E - Energía | I2: 50 - Otros | J2: ZART - Obras de arte | K2: 60121001 - Pinturas | L2: 6740 | M2: =+LEFT(D2,11) -> CMI01030400 | N2: =+LEFT(G2,9) -> ART371000 | O2: =+LEFT(H2,1) -> E | P2: =+LEFT(I2,2) -> 50 | Q2: =+LEFT(J2,4) -> ZART | R2: =+LEFT(K2,8) -> 60121001
A3: 010535 | B3: GRIFO | D3: CMI02050200 - Artefactos Sanitarios | F3: DEN | G3: CON251100 - Artefactos Sanitario | H3: E - Energía | I3: 50 - Otros | J3: ZCON - Materiales d/Construcción | K3: 30181700 - Grifos. | L3: 6741 | M3: =+LEFT(D3,11) -> CMI02050200 | N3: =+LEFT(G3,9) -> CON251100 | O3: =+LEFT(H3,1) -> E | P3: =+LEFT(I3,2) -> 50 | Q3: =+LEFT(J3,4) -> ZCON | R3: =+LEFT(K3,8) -> 30181700
A4: 010648 | B4: DUCHA DE BAÑO | D4: CMI02050100 - Accesorios | F4: DEN | G4: CON251100 - Artefactos Sanitario | H4: E - Energía | I4: 50 - Otros | J4: ZCON - Materiales d/Construcción | K4: 30181801 - Pomo de ducha | L4: 6742 | M4: =+LEFT(D4,11) -> CMI02050100 | N4: =+LEFT(G4,9) -> CON251100 | O4: =+LEFT(H4,1) -> E | P4: =+LEFT(I4,2) -> 50 | Q4: =+LEFT(J4,4) -> ZCON | R4: =+LEFT(K4,8) -> 30181801
A5: 015238 | B5: DEPOSITO | D5: CMI02090600 - Hidraulicos_Neumaticos | F5: DEN | G5: CON251000 - Accesorios | H5: E - Energía | I5: 50 - Otros | J5: ZCON - Materiales d/Construcción | K5: 24111810 - Tanques de almacenamiento agua | L5: 6743 | M5: =+LEFT(D5,11) -> CMI02090600 | N5: =+LEFT(G5,9) -> CON251000 | O5: =+LEFT(H5,1) -> E | P5: =+LEFT(I5,2) -> 50 | Q5: =+LEFT(J5,4) -> ZCON | R5: =+LEFT(K5,8) -> 24111810
A6: 015567 | B6: ARENA:CONSTRUCCION | D6: CMI02051500 - Piedrín y Arena | F6: DEN | G6: SUM231200 - Consumibles | H6: E - Energía | I6: 50 - Otros | J6: ZCON - Materiales d/Construcción | K6: 11111701 - Arena de sílice | L6: 6744 | M6: =+LEFT(D6,11) -> CMI02051500 | N6: =+LEFT(G6,9) -> SUM231200 | O6: =+LEFT(H6,1) -> E | P6: =+LEFT(I6,2) -> 50 | Q6: =+LEFT(J6,4) -> ZCON | R6: =+LEFT(K6,8) -> 11111701
A7: 015612 | B7: AZULEJOS:SUELO;CERAMICA | D7: CMI02051700 - Pisos y Azulejos | E7: 6 | F7: DEN | G7: SUM231200 - Consumibles | H7: E - Energía | I7: 50 - Otros | J7: ZCON - Materiales d/Construcción | K7: 30131704 - Losas o baldosas de cerámica | L7: 6745 | M7: =+LEFT(D7,11) -> CMI02051700 | N7: =+LEFT(G7,9) -> SUM231200 | O7: =+LEFT(H7,1) -> E | P7: =+LEFT(I7,2) -> 50 | Q7: =+LEFT(J7,4) -> ZCON | R7: =+LEFT(K7,8) -> 30131704
A8: 045346 | B8: CURADOR:CONCRETO | D8: CMI02180300 - Otros químicos | F8: DEN | G8: CON251300 - Concret/cemento/Adit | H8: E - Energía | I8: 50 - Otros | J8: ZCON - Materiales d/Construcción | K8: 12162301 - Agentes curado trans. por agua | L8: 6746 | M8: =+LEFT(D8,11) -> CMI02180300 | N8: =+LEFT(G8,9) -> CON251300 | O8: =+LEFT(H8,1) -> E | P8: =+LEFT(I8,2) -> 50 | Q8: =+LEFT(J8,4) -> ZCON | R8: =+LEFT(K8,8) -> 12162301
A9: 045409 | B9: PINTURA:ACRILICA | D9: CMI02051600 - Pinturas y Solventes | F9: DEN | G9: SUM231200 - Consumibles | H9: E - Energía | I9: 50 - Otros | J9: ZCON - Materiales d/Construcción | K9: 31211508 - Pinturas acrílicas | L9: 6747 | M9: =+LEFT(D9,11) -> CMI02051600 | N9: =+LEFT(G9,9) -> SUM231200 | O9: =+LEFT(H9,1) -> E | P9: =+LEFT(I9,2) -> 50 | Q9: =+LEFT(J9,4) -> ZCON | R9: =+LEFT(K9,8) -> 31211508
A10: 045555 | B10: COMPUESTO:SELLANTE | D10: CMI02051600 - Pinturas y Solventes | F10: DEN | G10: SUM231200 - Consumibles | H10: E - Energía | I10: 50 - Otros | J10: ZCON - Materiales d/Construcción | K10: 31201600 - Otros adhesivos y selladores | L10: 6748 | M10: =+LEFT(D10,11) -> CMI02051600 | N10: =+LEFT(G10,9) -> SUM231200 | O10: =+LEFT(H10,1) -> E | P10: =+LEFT(I10,2) -> 50 | Q10: =+LEFT(J10,4) -> ZCON | R10: =+LEFT(K10,8) -> 31201600
A11: 050395 | B11: LAMINA DE PLASTICO | D11: CMI03080500 - Otros-Empaques Especializados | F11: DEN | G11: SUM231200 - Consumibles | H11: E - Energía | I11: 50 - Otros | J11: ZCON - Materiales d/Construcción | K11: 30102015 - Lámina de plástico | L11: 6749 | M11: =+LEFT(D11,11) -> CMI03080500 | N11: =+LEFT(G11,9) -> SUM231200 | O11: =+LEFT(H11,1) -> E | P11: =+LEFT(I11,2) -> 50 | Q11: =+LEFT(J11,4) -> ZCON | R11: =+LEFT(K11,8) -> 30102015
A12: 050631 | B12: ANGULO:ALUMINIO | D12: CMI02051400 - Perfiles | F12: DEN | G12: SUM231200 - Consumibles | H12: E - Energía | I12: 50 - Otros | J12: ZCON - Materiales d/Construcción | K12: 30101506 - Ángulos de aluminio | L12: 6750 | M12: =+LEFT(D12,11) -> CMI02051400 | N12: =+LEFT(G12,9) -> SUM231200 | O12: =+LEFT(H12,1) -> E | P12: =+LEFT(I12,2) -> 50 | Q12: =+LEFT(J12,4) -> ZCON | R12: =+LEFT(K12,8) -> 30101506
A13: 050751 | B13: VIGA | D13: CMI02051400 - Perfiles | F13: DEN | G13: SUM231200 - Consumibles | H13: E - Energía | I13: 50 - Otros | J13: ZCON - Materiales d/Construcción | K13: 30101700 - Vigas | L13: 6751 | M13: =+LEFT(D13,11) -> CMI02051400 | N13: =+LEFT(G13,9) -> SUM231200 | O13: =+LEFT(H13,1) -> E | P13: =+LEFT(I13,2) -> 50 | Q13: =+LEFT(J13,4) -> ZCON | R13: =+LEFT(K13,8) -> 30101700
A14: 081807 | B14: TABLON | D14: CMI02051100 - Madera y derivados | F14: DEN | G14: SUM231200 - Consumibles | H14: E - Energía | I14: 50 - Otros | J14: ZCON - Materiales d/Construcción | K14: 30103605 - Tablones de madera | L14: 6752 | M14: =+LEFT(D14,11) -> CMI02051100 | N14: =+LEFT(G14,9) -> SUM231200 | O14: =+LEFT(H14,1) -> E | P14: =+LEFT(I14,2) -> 50 | Q14: =+LEFT(J14,4) -> ZCON | R14: =+LEFT(K14,8) -> 30103605
A15: 083674 | B15: PINTURA:REVESTIMIENTO | D15: CMI02051600 - Pinturas y Solventes | F15: DEN | G15: REP211100 - Rpto. AutomMecanico | H15: E - Energía | I15: 50 - Otros | J15: ZCON - Materiales d/Construcción | K15: 31211504 - Pinturas de revestimiento | L15: 6753 | M15: =+LEFT(D15,11) -> CMI02051600 | N15: =+LEFT(G15,9) -> REP211100 | O15: =+LEFT(H15,1) -> E | P15: =+LEFT(I15,2) -> 50 | Q15: =+LEFT(J15,4) -> ZCON | R15: =+LEFT(K15,8) -> 31211504
A16: 085771 | B16: ADITIVO | D16: CMI02050400 - Concreto, Cemento y Aditivos | F16: DEN | G16: SUM231200 - Consumibles | H16: E - Energía | I16: 50 - Otros | J16: ZCON - Materiales d/Construcción | K16: 12162305 - Aditivo de concreto | L16: 6754 | M16: =+LEFT(D16,11) -> CMI02050400 | N16: =+LEFT(G16,9) -> SUM231200 | O16: =+LEFT(H16,1) -> E | P16: =+LEFT(I16,2) -> 50 | Q16: =+LEFT(J16,4) -> ZCON | R16: =+LEFT(K16,8) -> 12162305
A17: 086456 | B17: CANAL | D17: CMI02051400 - Perfiles | F17: DEN | G17: SUM231200 - Consumibles | H17: E - Energía | I17: 50 - Otros | J17: ZCON - Materiales d/Construcción | K17: 30101800 - Conductos | L17: 6755 | M17: =+LEFT(D17,11) -> CMI02051400 | N17: =+LEFT(G17,9) -> SUM231200 | O17: =+LEFT(H17,1) -> E | P17: =+LEFT(I17,2) -> 50 | Q17: =+LEFT(J17,4) -> ZCON | R17: =+LEFT(K17,8) -> 30101800
A18: 088536 | B18: POSTE | D18: CMI02051300 - Otros-Mat de Construcción | F18: DEN | G18: SEG221000 - EquipSeguridad Indus | H18: E - Energía | I18: 50 - Otros | J18: ZCON - Materiales d/Construcción | K18: 30102900 - Pilares | L18: 6756 | M18: =+LEFT(D18,11) -> CMI02051300 | N18: =+LEFT(G18,9) -> SEG221000 | O18: =+LEFT(H18,1) -> E | P18: =+LEFT(I18,2) -> 50 | Q18: =+LEFT(J18,4) -> ZCON | R18: =+LEFT(K18,8) -> 30102900
A19: 088802 | B19: VARILLA | D19: CMI02050700 - Hierro | F19: DEN | G19: SUM231100 - Accesorios Mecánicos | H19: E - Energía | I19: 50 - Otros | J19: ZCON - Materiales d/Construcción | K19: 30102400 - Varillas | L19: 6757 | M19: =+LEFT(D19,11) -> CMI02050700 | N19: =+LEFT(G19,9) -> SUM231100 | O19: =+LEFT(H19,1) -> E | P19: =+LEFT(I19,2) -> 50 | Q19: =+LEFT(J19,4) -> ZCON | R19: =+LEFT(K19,8) -> 30102400
... A67: 050809 | B67: LAMINA:HIERRO | D67: CMI02051000 - Laminas | F67: DEN | G67: CON251800 - Laminas | H67: E - Energía | I67: 50 - Otros | J67: ZCON - Materiales d/Construcción | K67: 30102203 - Placa de hierro | L67: 6805 | M67: =+LEFT(D67,11) -> CMI02051000 | N67: =+LEFT(G67,9) -> CON251800 | O67: =+LEFT(H67,1) -> E | P67: =+LEFT(I67,2) -> 50 | Q67: =+LEFT(J67,4) -> ZCON | R67: =+LEFT(K67,8) -> 30102203
A68: 050814 | B68: LAMINA:ACERO | D68: CMI02051000 - Laminas | E68: 6 | F68: DEN | G68: CON251800 - Laminas | H68: E - Energía | I68: 50 - Otros | J68: ZCON - Materiales d/Construcción | K68: 30102004 - Lámina de acero | L68: 6806 | M68: =+LEFT(D68,11) -> CMI02051000 | N68: =+LEFT(G68,9) -> CON251800 | O68: =+LEFT(H68,1) -> E | P68: =+LEFT(I68,2) -> 50 | Q68: =+LEFT(J68,4) -> ZCON | R68: =+LEFT(K68,8) -> 30102004
A69: 050857 | B69: PERFIL:HIERRO | D69: CMI02051400 - Perfiles | F69: DEN | G69: CON252000 - Perfiles | H69: E - Energía | I69: 50 - Otros | J69: ZCON - Materiales d/Construcción | K69: 30102303 - Perfiles de hierro | L69: 6807 | M69: =+LEFT(D69,11) -> CMI02051400 | N69: =+LEFT(G69,9) -> CON252000 | O69: =+LEFT(H69,1) -> E | P69: =+LEFT(I69,2) -> 50 | Q69: =+LEFT(J69,4) -> ZCON | R69: =+LEFT(K69,8) -> 30102303
A70: 050886 | B70: LAMINA:METAL | D70: CMI02051000 - Laminas | F70: DEN | G70: CON251800 - Laminas | H70: E - Energía | I70: 50 - Otros | J70: ZCON - Materiales d/Construcción | K70: 30102000 - Hoja | L70: 6808 | M70: =+LEFT(D70,11) -> CMI02051000 | N70: =+LEFT(G70,9) -> CON251800 | O70: =+LEFT(H70,1) -> E | P70: =+LEFT(I70,2) -> 50 | Q70: =+LEFT(J70,4) -> ZCON | R70: =+LEFT(K70,8) -> 30102000
A71: 050902 | B71: LAMINA:ACERO INOX | D71: CMI02051000 - Laminas | F71: DEN | G71: CON251800 - Laminas | H71: E - Energía | I71: 50 - Otros | J71: ZCON - Materiales d/Construcción | K71: 30102005 - Lámina de acero inoxidable | L71: 6809 | M71: =+LEFT(D71,11) -> CMI02051000 | N71: =+LEFT(G71,9) -> CON251800 | O71: =+LEFT(H71,1) -> E | P71: =+LEFT(I71,2) -> 50 | Q71: =+LEFT(J71,4) -> ZCON | R71: =+LEFT(K71,8) -> 30102005
A72: 050906 | B72: LAMINA:MADERA | D72: CMI02051000 - Laminas | F72: DEN | G72: CON251900 - Madera y derivados | H72: E - Energía | I72: 50 - Otros | J72: ZCON - Materiales d/Construcción | K72: 30103604 - Revestimiento o láminas madera | L72: 6810 | M72: =+LEFT(D72,11) -> CMI02051000 | N72: =+LEFT(G72,9) -> CON251900 | O72: =+LEFT(H72,1) -> E | P72: =+LEFT(I72,2) -> 50 | Q72: =+LEFT(J72,4) -> ZCON | R72: =+LEFT(K72,8) -> 30103604
A73: 051265 | B73: VIGA:CEMENTO | D73: CMI02050400 - Concreto, Cemento y Aditivos | F73: DEN | G73: CON251300 - Concret/cemento/Adit | H73: E - Energía | I73: 50 - Otros | J73: ZCON - Materiales d/Construcción | K73: 30101717 - Vigas de concreto | L73: 6811 | M73: =+LEFT(D73,11) -> CMI02050400 | N73: =+LEFT(G73,9) -> CON251300 | O73: =+LEFT(H73,1) -> E | P73: =+LEFT(I73,2) -> 50 | Q73: =+LEFT(J73,4) -> ZCON | R73: =+LEFT(K73,8) -> 30101717
A74: 067504 | B74: CAL HIDRATADA | D74: CMI02050400 - Concreto, Cemento y Aditivos | F74: DEN | G74: CON251300 - Concret/cemento/Adit | H74: E - Energía | I74: 50 - Otros | J74: ZCON - Materiales d/Construcción | K74: 30111607 - Cal viva | L74: 6812 | M74: =+LEFT(D74,11) -> CMI02050400 | N74: =+LEFT(G74,9) -> CON251300 | O74: =+LEFT(H74,1) -> E | P74: =+LEFT(I74,2) -> 50 | Q74: =+LEFT(J74,4) -> ZCON | R74: =+LEFT(K74,8) -> 30111607
A75: 067736 | B75: TIERRA | D75: CMI02051500 - Piedrín y Arena | F75: DEN | G75: CON252100 - Piedrín y Arena | H75: E - Energía | I75: 50 - Otros | J75: ZCON - Materiales d/Construcción | K75: 11111501 - Tierra | L75: 6813 | M75: =+LEFT(D75,11) -> CMI02051500 | N75: =+LEFT(G75,9) -> CON252100 | O75: =+LEFT(H75,1) -> E | P75: =+LEFT(I75,2) -> 50 | Q75: =+LEFT(J75,4) -> ZCON | R75: =+LEFT(K75,8) -> 11111501
A76: 070495 | B76: DIGESTOR | D76: CMI02051300 - Otros-Mat de Construcción | F76: DEN | G76: CON251000 - Accesorios | H76: E - Energía | I76: 50 - Otros | J76: ZCON - Materiales d/Construcción | K76: 23151804 - React/fermentadores digestores | L76: 6814 | M76: =+LEFT(D76,11) -> CMI02051300 | N76: =+LEFT(G76,9) -> CON251000 | O76: =+LEFT(H76,1) -> E | P76: =+LEFT(I76,2) -> 50 | Q76: =+LEFT(J76,4) -> ZCON | R76: =+LEFT(K76,8) -> 23151804
A77: 071419 | B77: RETARDANTE AL FUEGO | D77: CMI02051300 - Otros-Mat de Construcción | F77: DEN | G77: CON252200 - Pinturas y solventes | H77: E - Energía | I77: 50 - Otros | J77: ZCON - Materiales d/Construcción | K77: 12162100 - Retardadores de llama | L77: 6815 | M77: =+LEFT(D77,11) -> CMI02051300 | N77: =+LEFT(G77,9) -> CON252200 | O77: =+LEFT(H77,1) -> E | P77: =+LEFT(I77,2) -> 50 | Q77: =+LEFT(J77,4) -> ZCON | R77: =+LEFT(K77,8) -> 12162100
A78: 071806 | B78: GEOMEMBRANA | D78: CMI02051300 - Otros-Mat de Construcción | F78: DEN | G78: CON251400 - Fijación y Anclajes | H78: E - Energía | I78: 50 - Otros | J78: ZCON - Materiales d/Construcción | K78: 30121701 - Geomalla | L78: 6816 | M78: =+LEFT(D78,11) -> CMI02051300 | N78: =+LEFT(G78,9) -> CON251400 | O78: =+LEFT(H78,1) -> E | P78: =+LEFT(I78,2) -> 50 | Q78: =+LEFT(J78,4) -> ZCON | R78: =+LEFT(K78,8) -> 30121701
A79: 071810 | B79: GEOTEXTIL | D79: CMI02051300 - Otros-Mat de Construcción | F79: DEN | G79: CON251400 - Fijación y Anclajes | H79: E - Energía | I79: 50 - Otros | J79: ZCON - Materiales d/Construcción | K79: 30121702 - Geotextil | L79: 6817 | M79: =+LEFT(D79,11) -> CMI02051300 | N79: =+LEFT(G79,9) -> CON251400 | O79: =+LEFT(H79,1) -> E | P79: =+LEFT(I79,2) -> 50 | Q79: =+LEFT(J79,4) -> ZCON | R79: =+LEFT(K79,8) -> 30121702
A80: 078852 | B80: GAVION COLCHON | D80: CMI02051300 - Otros-Mat de Construcción | F80: DEN | G80: CON252100 - Piedrín y Arena | H80: E - Energía | I80: 50 - Otros | J80: ZCON - Materiales d/Construcción | K80: 31163401 - Gavión | L80: 6818 | M80: =+LEFT(D80,11) -> CMI02051300 | N80: =+LEFT(G80,9) -> CON252100 | O80: =+LEFT(H80,1) -> E | P80: =+LEFT(I80,2) -> 50 | Q80: =+LEFT(J80,4) -> ZCON | R80: =+LEFT(K80,8) -> 31163401
... A135: 070102 | B135: INHIBIDOR CORROSION | D135: CMI02030100 - Grasas Industriales | F135: DEN | G135: LUB261000 - Grasas Industriales | H135: E - Energía | I135: 50 - Otros | J135: ZLUB - Combustibles y Lubricante | K135: 15121802 - Lubricante anti – corrosión | L135: 6873 | M135: =+LEFT(D135,11) -> CMI02030100 | N135: =+LEFT(G135,9) -> LUB261000 | O135: =+LEFT(H135,1) -> E | P135: =+LEFT(I135,2) -> 50 | Q135: =+LEFT(J135,4) -> ZLUB | R135: =+LEFT(K135,8) -> 15121802
A136: 073066 | B136: GRASA LUBRICANTE | D136: CMI02030300 - Lubricantes Industriales | E136: 6 | F136: DEN | G136: LUB261000 - Grasas Industriales | H136: E - Energía | I136: 10 - Energía | J136: ZLUB - Combustibles y Lubricante | K136: 27112914 - Lubricador de grasa | L136: 6874 | M136: =+LEFT(D136,11) -> CMI02030300 | N136: =+LEFT(G136,9) -> LUB261000 | O136: =+LEFT(H136,1) -> E | P136: =+LEFT(I136,2) -> 10 | Q136: =+LEFT(J136,4) -> ZLUB | R136: =+LEFT(K136,8) -> 27112914
A137: 087912 | B137: LUBRICANTE | D137: CMI02030300 - Lubricantes Industriales | F137: DEN | G137: LUB261200 - LubricanIndustriales | H137: E - Energía | I137: 50 - Otros | J137: ZLUB - Combustibles y Lubricante | K137: 15121501 - Aceite motor | L137: 6875 | M137: =+LEFT(D137,11) -> CMI02030300 | N137: =+LEFT(G137,9) -> LUB261200 | O137: =+LEFT(H137,1) -> E | P137: =+LEFT(I137,2) -> 50 | Q137: =+LEFT(J137,4) -> ZLUB | R137: =+LEFT(K137,8) -> 15121501
A138: 007055 | B138: ROSCADORA:ELECTRICA | D138: CMI01020300 - Equipo Industrial | F138: DEN | G138: SUM231400 - Herram d/Eléctricas | H138: E - Energía | I138: 50 - Otros | J138: ZMAQ - Maquinaria | K138: 23241642 - Roscadora de velocidad | L138: 6876 | M138: =+LEFT(D138,11) -> CMI01020300 | N138: =+LEFT(G138,9) -> SUM231400 | O138: =+LEFT(H138,1) -> E | P138: =+LEFT(I138,2) -> 50 | Q138: =+LEFT(J138,4) -> ZMAQ | R138: =+LEFT(K138,8) -> 23241642
A139: 086626 | B139: COMPRESOR | D139: CMI01020300 - Equipo Industrial | F139: DEN | G139: REP201100 - Rpto.Ind/Mecánicos | H139: E - Energía | I139: 50 - Otros | J139: ZMAQ - Maquinaria | K139: 40151600 - Compresores | L139: 6877 | M139: =+LEFT(D139,11) -> CMI01020300 | N139: =+LEFT(G139,9) -> REP201100 | O139: =+LEFT(H139,1) -> E | P139: =+LEFT(I139,2) -> 50 | Q139: =+LEFT(J139,4) -> ZMAQ | R139: =+LEFT(K139,8) -> 40151600
A140: 011646 | B140: EQUIPO;LIMPIEZA;ELEC | D140: CMI01020300 - Equipo Industrial | F140: DEN | G140: SUM231600 - Herramienta Mecánica | H140: E - Energía | I140: 50 - Otros | J140: ZMAQ - Maquinaria | K140: 72153504 - Limpieza chorro agua alta pres | L140: 6878 | M140: =+LEFT(D140,11) -> CMI01020300 | N140: =+LEFT(G140,9) -> SUM231600 | O140: =+LEFT(H140,1) -> E | P140: =+LEFT(I140,2) -> 50 | Q140: =+LEFT(J140,4) -> ZMAQ | R140: =+LEFT(K140,8) -> 72153504
A141: 003881 | B141: BOTE:INFLABLE | D141: CMI01060800 - Otros-Vehículos | F141: DEN | G141: MAQ351000 - Maquinaria | H141: E - Energía | I141: 50 - Otros | J141: ZMAQ - Maquinaria | K141: 25111516 - Bote de caucho inflable | L141: 6879 | M141: =+LEFT(D141,11) -> CMI01060800 | N141: =+LEFT(G141,9) -> MAQ351000 | O141: =+LEFT(H141,1) -> E | P141: =+LEFT(I141,2) -> 50 | Q141: =+LEFT(J141,4) -> ZMAQ | R141: =+LEFT(K141,8) -> 25111516
...
